2021-04-25 14:22:46,801 ERROR: Exception on /addposts [POST] [in C:\Users\lolof\PycharmProjects\nextdigital\venv\lib\site-packages\flask\app.py:1761]
Traceback (most recent call last):
  File "C:\Users\lolof\PycharmProjects\nextdigital\venv\lib\site-packages\flask\app.py", line 2292, in wsgi_app
    response = self.full_dispatch_request()
  File "C:\Users\lolof\PycharmProjects\nextdigital\venv\lib\site-packages\flask\app.py", line 1815, in full_dispatch_request
    rv = self.handle_user_exception(e)
  File "C:\Users\lolof\PycharmProjects\nextdigital\venv\lib\site-packages\flask\app.py", line 1718, in handle_user_exception
    reraise(exc_type, exc_value, tb)
  File "C:\Users\lolof\PycharmProjects\nextdigital\venv\lib\site-packages\flask\_compat.py", line 35, in reraise
    raise value
  File "C:\Users\lolof\PycharmProjects\nextdigital\venv\lib\site-packages\flask\app.py", line 1813, in full_dispatch_request
    rv = self.dispatch_request()
  File "C:\Users\lolof\PycharmProjects\nextdigital\venv\lib\site-packages\flask\app.py", line 1799, in dispatch_request
    return self.view_functions[rule.endpoint](**req.view_args)
  File "C:\Users\lolof\PycharmProjects\nextdigital\venv\lib\site-packages\flask_login\utils.py", line 261, in decorated_view
    return func(*args, **kwargs)
  File "C:\Users\lolof\PycharmProjects\nextdigital\app\main\routes.py", line 76, in addposts
    filename=filename))
  File "C:\Users\lolof\PycharmProjects\nextdigital\venv\lib\site-packages\flask\helpers.py", line 356, in url_for
    return appctx.app.handle_url_build_error(error, endpoint, values)
  File "C:\Users\lolof\PycharmProjects\nextdigital\venv\lib\site-packages\flask\app.py", line 2061, in handle_url_build_error
    reraise(exc_type, exc_value, tb)
  File "C:\Users\lolof\PycharmProjects\nextdigital\venv\lib\site-packages\flask\_compat.py", line 35, in reraise
    raise value
  File "C:\Users\lolof\PycharmProjects\nextdigital\venv\lib\site-packages\flask\helpers.py", line 345, in url_for
    force_external=external)
  File "C:\Users\lolof\PycharmProjects\nextdigital\venv\lib\site-packages\werkzeug\routing.py", line 1776, in build
    raise BuildError(endpoint, values, method, self)
werkzeug.routing.BuildError: Could not build url for endpoint 'addposts' with values ['filename']. Did you mean 'main.addposts' instead?
2021-04-25 14:23:01,598 INFO: Microblog startup [in C:\Users\lolof\PycharmProjects\nextdigital\app\__init__.py:96]
2021-04-25 15:24:55,119 INFO: Microblog startup [in C:\Users\lolof\PycharmProjects\nextdigital\app\__init__.py:96]
2021-04-25 18:16:58,470 INFO: Microblog startup [in C:\Users\lolof\PycharmProjects\nextdigital\app\__init__.py:96]
2021-04-25 18:17:06,382 INFO: Microblog startup [in C:\Users\lolof\PycharmProjects\nextdigital\app\__init__.py:96]
2021-04-25 18:18:57,738 INFO: Microblog startup [in C:\Users\lolof\PycharmProjects\nextdigital\app\__init__.py:96]
2021-04-25 18:19:19,417 ERROR: Exception on /addposts [POST] [in C:\Users\lolof\PycharmProjects\nextdigital\venv\lib\site-packages\flask\app.py:1761]
Traceback (most recent call last):
  File "C:\Users\lolof\PycharmProjects\nextdigital\venv\lib\site-packages\flask\app.py", line 2292, in wsgi_app
    response = self.full_dispatch_request()
  File "C:\Users\lolof\PycharmProjects\nextdigital\venv\lib\site-packages\flask\app.py", line 1815, in full_dispatch_request
    rv = self.handle_user_exception(e)
  File "C:\Users\lolof\PycharmProjects\nextdigital\venv\lib\site-packages\flask\app.py", line 1718, in handle_user_exception
    reraise(exc_type, exc_value, tb)
  File "C:\Users\lolof\PycharmProjects\nextdigital\venv\lib\site-packages\flask\_compat.py", line 35, in reraise
    raise value
  File "C:\Users\lolof\PycharmProjects\nextdigital\venv\lib\site-packages\flask\app.py", line 1813, in full_dispatch_request
    rv = self.dispatch_request()
  File "C:\Users\lolof\PycharmProjects\nextdigital\venv\lib\site-packages\flask\app.py", line 1799, in dispatch_request
    return self.view_functions[rule.endpoint](**req.view_args)
  File "C:\Users\lolof\PycharmProjects\nextdigital\venv\lib\site-packages\flask_login\utils.py", line 261, in decorated_view
    return func(*args, **kwargs)
  File "C:\Users\lolof\PycharmProjects\nextdigital\app\main\routes.py", line 79, in addposts
    filename = secure_filename(newsform.fileName.file.filename)
AttributeError: 'FileField' object has no attribute 'file'
2021-04-25 18:23:15,292 INFO: Microblog startup [in C:\Users\lolof\PycharmProjects\nextdigital\app\__init__.py:96]
2021-04-25 18:23:28,598 ERROR: Exception on /addposts [POST] [in C:\Users\lolof\PycharmProjects\nextdigital\venv\lib\site-packages\flask\app.py:1761]
Traceback (most recent call last):
  File "C:\Users\lolof\PycharmProjects\nextdigital\venv\lib\site-packages\flask\app.py", line 2292, in wsgi_app
    response = self.full_dispatch_request()
  File "C:\Users\lolof\PycharmProjects\nextdigital\venv\lib\site-packages\flask\app.py", line 1815, in full_dispatch_request
    rv = self.handle_user_exception(e)
  File "C:\Users\lolof\PycharmProjects\nextdigital\venv\lib\site-packages\flask\app.py", line 1718, in handle_user_exception
    reraise(exc_type, exc_value, tb)
  File "C:\Users\lolof\PycharmProjects\nextdigital\venv\lib\site-packages\flask\_compat.py", line 35, in reraise
    raise value
  File "C:\Users\lolof\PycharmProjects\nextdigital\venv\lib\site-packages\flask\app.py", line 1813, in full_dispatch_request
    rv = self.dispatch_request()
  File "C:\Users\lolof\PycharmProjects\nextdigital\venv\lib\site-packages\flask\app.py", line 1799, in dispatch_request
    return self.view_functions[rule.endpoint](**req.view_args)
  File "C:\Users\lolof\PycharmProjects\nextdigital\venv\lib\site-packages\flask_login\utils.py", line 261, in decorated_view
    return func(*args, **kwargs)
  File "C:\Users\lolof\PycharmProjects\nextdigital\app\main\routes.py", line 79, in addposts
    filename = secure_filename(newsform.fileName.file.filename)
AttributeError: 'FileField' object has no attribute 'file'
2021-04-25 18:24:01,719 ERROR: Exception on /addposts [POST] [in C:\Users\lolof\PycharmProjects\nextdigital\venv\lib\site-packages\flask\app.py:1761]
Traceback (most recent call last):
  File "C:\Users\lolof\PycharmProjects\nextdigital\venv\lib\site-packages\flask\app.py", line 2292, in wsgi_app
    response = self.full_dispatch_request()
  File "C:\Users\lolof\PycharmProjects\nextdigital\venv\lib\site-packages\flask\app.py", line 1815, in full_dispatch_request
    rv = self.handle_user_exception(e)
  File "C:\Users\lolof\PycharmProjects\nextdigital\venv\lib\site-packages\flask\app.py", line 1718, in handle_user_exception
    reraise(exc_type, exc_value, tb)
  File "C:\Users\lolof\PycharmProjects\nextdigital\venv\lib\site-packages\flask\_compat.py", line 35, in reraise
    raise value
  File "C:\Users\lolof\PycharmProjects\nextdigital\venv\lib\site-packages\flask\app.py", line 1813, in full_dispatch_request
    rv = self.dispatch_request()
  File "C:\Users\lolof\PycharmProjects\nextdigital\venv\lib\site-packages\flask\app.py", line 1799, in dispatch_request
    return self.view_functions[rule.endpoint](**req.view_args)
  File "C:\Users\lolof\PycharmProjects\nextdigital\venv\lib\site-packages\flask_login\utils.py", line 261, in decorated_view
    return func(*args, **kwargs)
  File "C:\Users\lolof\PycharmProjects\nextdigital\app\main\routes.py", line 79, in addposts
    filename = secure_filename(newsform.fileName.file.filename)
AttributeError: 'FileField' object has no attribute 'file'
2021-04-25 18:25:59,921 INFO: Microblog startup [in C:\Users\lolof\PycharmProjects\nextdigital\app\__init__.py:96]
2021-04-25 18:26:02,378 ERROR: Exception on /addposts [POST] [in C:\Users\lolof\PycharmProjects\nextdigital\venv\lib\site-packages\flask\app.py:1761]
Traceback (most recent call last):
  File "C:\Users\lolof\PycharmProjects\nextdigital\venv\lib\site-packages\flask\app.py", line 2292, in wsgi_app
    response = self.full_dispatch_request()
  File "C:\Users\lolof\PycharmProjects\nextdigital\venv\lib\site-packages\flask\app.py", line 1815, in full_dispatch_request
    rv = self.handle_user_exception(e)
  File "C:\Users\lolof\PycharmProjects\nextdigital\venv\lib\site-packages\flask\app.py", line 1718, in handle_user_exception
    reraise(exc_type, exc_value, tb)
  File "C:\Users\lolof\PycharmProjects\nextdigital\venv\lib\site-packages\flask\_compat.py", line 35, in reraise
    raise value
  File "C:\Users\lolof\PycharmProjects\nextdigital\venv\lib\site-packages\flask\app.py", line 1813, in full_dispatch_request
    rv = self.dispatch_request()
  File "C:\Users\lolof\PycharmProjects\nextdigital\venv\lib\site-packages\flask\app.py", line 1799, in dispatch_request
    return self.view_functions[rule.endpoint](**req.view_args)
  File "C:\Users\lolof\PycharmProjects\nextdigital\venv\lib\site-packages\flask_login\utils.py", line 261, in decorated_view
    return func(*args, **kwargs)
  File "C:\Users\lolof\PycharmProjects\nextdigital\app\main\routes.py", line 79, in addposts
    filename = secure_filename(newsform.fileName)
  File "C:\Users\lolof\PycharmProjects\nextdigital\venv\lib\site-packages\werkzeug\utils.py", line 284, in secure_filename
    filename = filename.replace(sep, ' ')
AttributeError: 'FileField' object has no attribute 'replace'
2021-04-25 18:29:12,750 INFO: Microblog startup [in C:\Users\lolof\PycharmProjects\nextdigital\app\__init__.py:96]
