2021-04-29 03:33:01,562 ERROR: Exception on /move_news [GET] [in C:\Users\lolof\PycharmProjects\nextdigital\venv\lib\site-packages\flask\app.py:1761]
Traceback (most recent call last):
  File "C:\Users\lolof\PycharmProjects\nextdigital\venv\lib\site-packages\sqlalchemy\engine\base.py", line 1193, in _execute_context
    context)
  File "C:\Users\lolof\PycharmProjects\nextdigital\venv\lib\site-packages\sqlalchemy\engine\default.py", line 508, in do_execute
    cursor.execute(statement, parameters)
sqlite3.OperationalError: no such column: news_post.timestamp

The above exception was the direct cause of the following exception:

Traceback (most recent call last):
  File "C:\Users\lolof\PycharmProjects\nextdigital\venv\lib\site-packages\flask\app.py", line 2292, in wsgi_app
    response = self.full_dispatch_request()
  File "C:\Users\lolof\PycharmProjects\nextdigital\venv\lib\site-packages\flask\app.py", line 1815, in full_dispatch_request
    rv = self.handle_user_exception(e)
  File "C:\Users\lolof\PycharmProjects\nextdigital\venv\lib\site-packages\flask\app.py", line 1718, in handle_user_exception
    reraise(exc_type, exc_value, tb)
  File "C:\Users\lolof\PycharmProjects\nextdigital\venv\lib\site-packages\flask\_compat.py", line 35, in reraise
    raise value
  File "C:\Users\lolof\PycharmProjects\nextdigital\venv\lib\site-packages\flask\app.py", line 1813, in full_dispatch_request
    rv = self.dispatch_request()
  File "C:\Users\lolof\PycharmProjects\nextdigital\venv\lib\site-packages\flask\app.py", line 1799, in dispatch_request
    return self.view_functions[rule.endpoint](**req.view_args)
  File "C:\Users\lolof\PycharmProjects\nextdigital\app\main\routes.py", line 164, in move_news
    return render_template('move_news.html', move_news_menu=move_news_menu, news=news)
  File "C:\Users\lolof\PycharmProjects\nextdigital\venv\lib\site-packages\flask\templating.py", line 135, in render_template
    context, ctx.app)
  File "C:\Users\lolof\PycharmProjects\nextdigital\venv\lib\site-packages\flask\templating.py", line 117, in _render
    rv = template.render(context)
  File "C:\Users\lolof\PycharmProjects\nextdigital\venv\lib\site-packages\jinja2\asyncsupport.py", line 76, in render
    return original_render(self, *args, **kwargs)
  File "C:\Users\lolof\PycharmProjects\nextdigital\venv\lib\site-packages\jinja2\environment.py", line 1008, in render
    return self.environment.handle_exception(exc_info, True)
  File "C:\Users\lolof\PycharmProjects\nextdigital\venv\lib\site-packages\jinja2\environment.py", line 780, in handle_exception
    reraise(exc_type, exc_value, tb)
  File "C:\Users\lolof\PycharmProjects\nextdigital\venv\lib\site-packages\jinja2\_compat.py", line 37, in reraise
    raise value.with_traceback(tb)
  File "C:\Users\lolof\PycharmProjects\nextdigital\app\templates\move_news.html", line 2, in top-level template code
    {% import 'bootstrap/wtf.html' as wtf %}
  File "C:\Users\lolof\PycharmProjects\nextdigital\app\templates\base.html", line 1, in top-level template code
    {% extends 'bootstrap/base.html' %}
  File "C:\Users\lolof\PycharmProjects\nextdigital\venv\lib\site-packages\flask_bootstrap\templates\bootstrap\base.html", line 1, in top-level template code
    {% block doc -%}
  File "C:\Users\lolof\PycharmProjects\nextdigital\venv\lib\site-packages\flask_bootstrap\templates\bootstrap\base.html", line 4, in block "doc"
    {%- block html %}
  File "C:\Users\lolof\PycharmProjects\nextdigital\venv\lib\site-packages\flask_bootstrap\templates\bootstrap\base.html", line 20, in block "html"
    {% block body -%}
  File "C:\Users\lolof\PycharmProjects\nextdigital\venv\lib\site-packages\flask_bootstrap\templates\bootstrap\base.html", line 23, in block "body"
    {% block content -%}
  File "C:\Users\lolof\PycharmProjects\nextdigital\app\templates\base.html", line 57, in block "content"
    {% block current_app_content %}{% endblock %}
  File "C:\Users\lolof\PycharmProjects\nextdigital\app\templates\move_news.html", line 15, in block "current_app_content"
    {% for new in news %}
  File "C:\Users\lolof\PycharmProjects\nextdigital\venv\lib\site-packages\sqlalchemy\orm\query.py", line 2935, in __iter__
    return self._execute_and_instances(context)
  File "C:\Users\lolof\PycharmProjects\nextdigital\venv\lib\site-packages\sqlalchemy\orm\query.py", line 2958, in _execute_and_instances
    result = conn.execute(querycontext.statement, self._params)
  File "C:\Users\lolof\PycharmProjects\nextdigital\venv\lib\site-packages\sqlalchemy\engine\base.py", line 948, in execute
    return meth(self, multiparams, params)
  File "C:\Users\lolof\PycharmProjects\nextdigital\venv\lib\site-packages\sqlalchemy\sql\elements.py", line 269, in _execute_on_connection
    return connection._execute_clauseelement(self, multiparams, params)
  File "C:\Users\lolof\PycharmProjects\nextdigital\venv\lib\site-packages\sqlalchemy\engine\base.py", line 1060, in _execute_clauseelement
    compiled_sql, distilled_params
  File "C:\Users\lolof\PycharmProjects\nextdigital\venv\lib\site-packages\sqlalchemy\engine\base.py", line 1200, in _execute_context
    context)
  File "C:\Users\lolof\PycharmProjects\nextdigital\venv\lib\site-packages\sqlalchemy\engine\base.py", line 1413, in _handle_dbapi_exception
    exc_info
  File "C:\Users\lolof\PycharmProjects\nextdigital\venv\lib\site-packages\sqlalchemy\util\compat.py", line 203, in raise_from_cause
    reraise(type(exception), exception, tb=exc_tb, cause=cause)
  File "C:\Users\lolof\PycharmProjects\nextdigital\venv\lib\site-packages\sqlalchemy\util\compat.py", line 186, in reraise
    raise value.with_traceback(tb)
  File "C:\Users\lolof\PycharmProjects\nextdigital\venv\lib\site-packages\sqlalchemy\engine\base.py", line 1193, in _execute_context
    context)
  File "C:\Users\lolof\PycharmProjects\nextdigital\venv\lib\site-packages\sqlalchemy\engine\default.py", line 508, in do_execute
    cursor.execute(statement, parameters)
sqlalchemy.exc.OperationalError: (sqlite3.OperationalError) no such column: news_post.timestamp [SQL: 'SELECT movenews_post.id AS movenews_post_id, movenews_post.posttitle AS movenews_post_posttitle, movenews_post.body AS movenews_post_body, movenews_post.cover_name AS movenews_post_cover_name, movenews_post.timestamp AS movenews_post_timestamp, movenews_post.user_id AS movenews_post_user_id \nFROM movenews_post ORDER BY news_post.timestamp DESC'] (Background on this error at: http://sqlalche.me/e/e3q8)
2021-04-29 03:34:19,894 INFO: Microblog startup [in C:\Users\lolof\PycharmProjects\nextdigital\app\__init__.py:94]
2021-04-29 03:45:30,136 INFO: Microblog startup [in C:\Users\lolof\PycharmProjects\nextdigital\app\__init__.py:94]
2021-04-29 03:46:28,243 INFO: Microblog startup [in C:\Users\lolof\PycharmProjects\nextdigital\app\__init__.py:94]
2021-04-29 03:49:46,002 ERROR: Exception on /apple_daily/33 [GET] [in C:\Users\lolof\PycharmProjects\nextdigital\venv\lib\site-packages\flask\app.py:1761]
Traceback (most recent call last):
  File "C:\Users\lolof\PycharmProjects\nextdigital\venv\lib\site-packages\flask\app.py", line 2292, in wsgi_app
    response = self.full_dispatch_request()
  File "C:\Users\lolof\PycharmProjects\nextdigital\venv\lib\site-packages\flask\app.py", line 1815, in full_dispatch_request
    rv = self.handle_user_exception(e)
  File "C:\Users\lolof\PycharmProjects\nextdigital\venv\lib\site-packages\flask\app.py", line 1718, in handle_user_exception
    reraise(exc_type, exc_value, tb)
  File "C:\Users\lolof\PycharmProjects\nextdigital\venv\lib\site-packages\flask\_compat.py", line 35, in reraise
    raise value
  File "C:\Users\lolof\PycharmProjects\nextdigital\venv\lib\site-packages\flask\app.py", line 1813, in full_dispatch_request
    rv = self.dispatch_request()
  File "C:\Users\lolof\PycharmProjects\nextdigital\venv\lib\site-packages\flask\app.py", line 1799, in dispatch_request
    return self.view_functions[rule.endpoint](**req.view_args)
  File "C:\Users\lolof\PycharmProjects\nextdigital\app\main\routes.py", line 181, in apple_daily_route
    image_url = os.path.join(current_app.config['UPLOAD_FOLDER'],new.cover_name)
AttributeError: 'NoneType' object has no attribute 'cover_name'
2021-04-29 03:49:51,846 ERROR: Exception on /apple_daily/33 [GET] [in C:\Users\lolof\PycharmProjects\nextdigital\venv\lib\site-packages\flask\app.py:1761]
Traceback (most recent call last):
  File "C:\Users\lolof\PycharmProjects\nextdigital\venv\lib\site-packages\flask\app.py", line 2292, in wsgi_app
    response = self.full_dispatch_request()
  File "C:\Users\lolof\PycharmProjects\nextdigital\venv\lib\site-packages\flask\app.py", line 1815, in full_dispatch_request
    rv = self.handle_user_exception(e)
  File "C:\Users\lolof\PycharmProjects\nextdigital\venv\lib\site-packages\flask\app.py", line 1718, in handle_user_exception
    reraise(exc_type, exc_value, tb)
  File "C:\Users\lolof\PycharmProjects\nextdigital\venv\lib\site-packages\flask\_compat.py", line 35, in reraise
    raise value
  File "C:\Users\lolof\PycharmProjects\nextdigital\venv\lib\site-packages\flask\app.py", line 1813, in full_dispatch_request
    rv = self.dispatch_request()
  File "C:\Users\lolof\PycharmProjects\nextdigital\venv\lib\site-packages\flask\app.py", line 1799, in dispatch_request
    return self.view_functions[rule.endpoint](**req.view_args)
  File "C:\Users\lolof\PycharmProjects\nextdigital\app\main\routes.py", line 181, in apple_daily_route
    image_url = os.path.join(current_app.config['UPLOAD_FOLDER'],new.cover_name)
AttributeError: 'NoneType' object has no attribute 'cover_name'
