2021-04-29 03:29:57,910 ERROR: Exception on /add_move_news_posts [POST] [in C:\Users\lolof\PycharmProjects\nextdigital\venv\lib\site-packages\flask\app.py:1761]
Traceback (most recent call last):
  File "C:\Users\lolof\PycharmProjects\nextdigital\venv\lib\site-packages\flask\app.py", line 2292, in wsgi_app
    response = self.full_dispatch_request()
  File "C:\Users\lolof\PycharmProjects\nextdigital\venv\lib\site-packages\flask\app.py", line 1815, in full_dispatch_request
    rv = self.handle_user_exception(e)
  File "C:\Users\lolof\PycharmProjects\nextdigital\venv\lib\site-packages\flask\app.py", line 1718, in handle_user_exception
    reraise(exc_type, exc_value, tb)
  File "C:\Users\lolof\PycharmProjects\nextdigital\venv\lib\site-packages\flask\_compat.py", line 35, in reraise
    raise value
  File "C:\Users\lolof\PycharmProjects\nextdigital\venv\lib\site-packages\flask\app.py", line 1811, in full_dispatch_request
    rv = self.preprocess_request()
  File "C:\Users\lolof\PycharmProjects\nextdigital\venv\lib\site-packages\flask\app.py", line 2087, in preprocess_request
    rv = func()
  File "C:\Users\lolof\PycharmProjects\nextdigital\app\main\routes.py", line 20, in before_request
    if current_user.is_authenticated:
  File "C:\Users\lolof\PycharmProjects\nextdigital\venv\lib\site-packages\werkzeug\local.py", line 347, in __getattr__
    return getattr(self._get_current_object(), name)
  File "C:\Users\lolof\PycharmProjects\nextdigital\venv\lib\site-packages\werkzeug\local.py", line 306, in _get_current_object
    return self.__local()
  File "C:\Users\lolof\PycharmProjects\nextdigital\venv\lib\site-packages\flask_login\utils.py", line 26, in <lambda>
    current_user = LocalProxy(lambda: _get_user())
  File "C:\Users\lolof\PycharmProjects\nextdigital\venv\lib\site-packages\flask_login\utils.py", line 335, in _get_user
    current_app.login_manager._load_user()
  File "C:\Users\lolof\PycharmProjects\nextdigital\venv\lib\site-packages\flask_login\login_manager.py", line 359, in _load_user
    return self.reload_user()
  File "C:\Users\lolof\PycharmProjects\nextdigital\venv\lib\site-packages\flask_login\login_manager.py", line 321, in reload_user
    user = self.user_callback(user_id)
  File "C:\Users\lolof\PycharmProjects\nextdigital\app\models.py", line 83, in load_user
    return User.query.get(int(id))
  File "C:\Users\lolof\PycharmProjects\nextdigital\venv\lib\site-packages\flask_sqlalchemy\__init__.py", line 512, in __get__
    mapper = orm.class_mapper(type)
  File "C:\Users\lolof\PycharmProjects\nextdigital\venv\lib\site-packages\sqlalchemy\orm\base.py", line 421, in class_mapper
    mapper = _inspect_mapped_class(class_, configure=configure)
  File "C:\Users\lolof\PycharmProjects\nextdigital\venv\lib\site-packages\sqlalchemy\orm\base.py", line 400, in _inspect_mapped_class
    mapper._configure_all()
  File "C:\Users\lolof\PycharmProjects\nextdigital\venv\lib\site-packages\sqlalchemy\orm\mapper.py", line 1272, in _configure_all
    configure_mappers()
  File "C:\Users\lolof\PycharmProjects\nextdigital\venv\lib\site-packages\sqlalchemy\orm\mapper.py", line 3029, in configure_mappers
    mapper._post_configure_properties()
  File "C:\Users\lolof\PycharmProjects\nextdigital\venv\lib\site-packages\sqlalchemy\orm\mapper.py", line 1828, in _post_configure_properties
    prop.init()
  File "C:\Users\lolof\PycharmProjects\nextdigital\venv\lib\site-packages\sqlalchemy\orm\interfaces.py", line 184, in init
    self.do_init()
  File "C:\Users\lolof\PycharmProjects\nextdigital\venv\lib\site-packages\sqlalchemy\orm\relationships.py", line 1659, in do_init
    self._generate_backref()
  File "C:\Users\lolof\PycharmProjects\nextdigital\venv\lib\site-packages\sqlalchemy\orm\relationships.py", line 1849, in _generate_backref
    (backref_key, self, m))
sqlalchemy.exc.ArgumentError: Error creating backref 'author' on relationship 'User.movenewsPost': property of that name exists on mapper 'Mapper|newsPost|news_post'
2021-04-29 03:30:36,817 INFO: Microblog startup [in C:\Users\lolof\PycharmProjects\nextdigital\app\__init__.py:94]
2021-04-29 03:32:58,654 INFO: Microblog startup [in C:\Users\lolof\PycharmProjects\nextdigital\app\__init__.py:94]
