2021-04-28 00:28:41,632 ERROR: Exception on /index [GET] [in C:\Users\lolof\PycharmProjects\nextdigital\venv\lib\site-packages\flask\app.py:1761]
Traceback (most recent call last):
  File "C:\Users\lolof\PycharmProjects\nextdigital\venv\lib\site-packages\flask\app.py", line 2292, in wsgi_app
    response = self.full_dispatch_request()
  File "C:\Users\lolof\PycharmProjects\nextdigital\venv\lib\site-packages\flask\app.py", line 1815, in full_dispatch_request
    rv = self.handle_user_exception(e)
  File "C:\Users\lolof\PycharmProjects\nextdigital\venv\lib\site-packages\flask\app.py", line 1718, in handle_user_exception
    reraise(exc_type, exc_value, tb)
  File "C:\Users\lolof\PycharmProjects\nextdigital\venv\lib\site-packages\flask\_compat.py", line 35, in reraise
    raise value
  File "C:\Users\lolof\PycharmProjects\nextdigital\venv\lib\site-packages\flask\app.py", line 1813, in full_dispatch_request
    rv = self.dispatch_request()
  File "C:\Users\lolof\PycharmProjects\nextdigital\venv\lib\site-packages\flask\app.py", line 1799, in dispatch_request
    return self.view_functions[rule.endpoint](**req.view_args)
  File "C:\Users\lolof\PycharmProjects\nextdigital\venv\lib\site-packages\flask_login\utils.py", line 261, in decorated_view
    return func(*args, **kwargs)
  File "C:\Users\lolof\PycharmProjects\nextdigital\app\main\routes.py", line 48, in index
    prev_url=prev_url,base_configuration=base_configuration)
  File "C:\Users\lolof\PycharmProjects\nextdigital\venv\lib\site-packages\flask\templating.py", line 135, in render_template
    context, ctx.app)
  File "C:\Users\lolof\PycharmProjects\nextdigital\venv\lib\site-packages\flask\templating.py", line 117, in _render
    rv = template.render(context)
  File "C:\Users\lolof\PycharmProjects\nextdigital\venv\lib\site-packages\jinja2\asyncsupport.py", line 76, in render
    return original_render(self, *args, **kwargs)
  File "C:\Users\lolof\PycharmProjects\nextdigital\venv\lib\site-packages\jinja2\environment.py", line 1008, in render
    return self.environment.handle_exception(exc_info, True)
  File "C:\Users\lolof\PycharmProjects\nextdigital\venv\lib\site-packages\jinja2\environment.py", line 780, in handle_exception
    reraise(exc_type, exc_value, tb)
  File "C:\Users\lolof\PycharmProjects\nextdigital\venv\lib\site-packages\jinja2\_compat.py", line 37, in reraise
    raise value.with_traceback(tb)
  File "C:\Users\lolof\PycharmProjects\nextdigital\app\templates\index.html", line 2, in top-level template code
    {% import 'bootstrap/wtf.html' as wtf %}
  File "C:\Users\lolof\PycharmProjects\nextdigital\app\templates\base.html", line 1, in top-level template code
    {% extends 'bootstrap/base.html' %}
  File "C:\Users\lolof\PycharmProjects\nextdigital\venv\lib\site-packages\flask_bootstrap\templates\bootstrap\base.html", line 1, in top-level template code
    {% block doc -%}
  File "C:\Users\lolof\PycharmProjects\nextdigital\venv\lib\site-packages\flask_bootstrap\templates\bootstrap\base.html", line 4, in block "doc"
    {%- block html %}
  File "C:\Users\lolof\PycharmProjects\nextdigital\venv\lib\site-packages\flask_bootstrap\templates\bootstrap\base.html", line 20, in block "html"
    {% block body -%}
  File "C:\Users\lolof\PycharmProjects\nextdigital\venv\lib\site-packages\flask_bootstrap\templates\bootstrap\base.html", line 23, in block "body"
    {% block content -%}
  File "C:\Users\lolof\PycharmProjects\nextdigital\app\templates\base.html", line 56, in block "content"
    {% block current_app_content %}{% endblock %}
  File "C:\Users\lolof\PycharmProjects\nextdigital\app\templates\index.html", line 9, in block "current_app_content"
    <img src="{{ url_for('static', filename=nextdigital_logo1.png) }}"  alt="nextdigital 1logo">
  File "C:\Users\lolof\PycharmProjects\nextdigital\venv\lib\site-packages\jinja2\environment.py", line 430, in getattr
    return getattr(obj, attribute)
jinja2.exceptions.UndefinedError: 'nextdigital_logo1' is undefined
2021-04-28 00:29:25,264 INFO: Microblog startup [in C:\Users\lolof\PycharmProjects\nextdigital\app\__init__.py:94]
2021-04-28 00:29:27,989 ERROR: Exception on /explore [GET] [in C:\Users\lolof\PycharmProjects\nextdigital\venv\lib\site-packages\flask\app.py:1761]
Traceback (most recent call last):
  File "C:\Users\lolof\PycharmProjects\nextdigital\venv\lib\site-packages\flask\app.py", line 2292, in wsgi_app
    response = self.full_dispatch_request()
  File "C:\Users\lolof\PycharmProjects\nextdigital\venv\lib\site-packages\flask\app.py", line 1815, in full_dispatch_request
    rv = self.handle_user_exception(e)
  File "C:\Users\lolof\PycharmProjects\nextdigital\venv\lib\site-packages\flask\app.py", line 1718, in handle_user_exception
    reraise(exc_type, exc_value, tb)
  File "C:\Users\lolof\PycharmProjects\nextdigital\venv\lib\site-packages\flask\_compat.py", line 35, in reraise
    raise value
  File "C:\Users\lolof\PycharmProjects\nextdigital\venv\lib\site-packages\flask\app.py", line 1813, in full_dispatch_request
    rv = self.dispatch_request()
  File "C:\Users\lolof\PycharmProjects\nextdigital\venv\lib\site-packages\flask\app.py", line 1799, in dispatch_request
    return self.view_functions[rule.endpoint](**req.view_args)
  File "C:\Users\lolof\PycharmProjects\nextdigital\venv\lib\site-packages\flask_login\utils.py", line 261, in decorated_view
    return func(*args, **kwargs)
  File "C:\Users\lolof\PycharmProjects\nextdigital\app\main\routes.py", line 114, in explore
    prev_url=prev_url)
  File "C:\Users\lolof\PycharmProjects\nextdigital\venv\lib\site-packages\flask\templating.py", line 135, in render_template
    context, ctx.app)
  File "C:\Users\lolof\PycharmProjects\nextdigital\venv\lib\site-packages\flask\templating.py", line 117, in _render
    rv = template.render(context)
  File "C:\Users\lolof\PycharmProjects\nextdigital\venv\lib\site-packages\jinja2\asyncsupport.py", line 76, in render
    return original_render(self, *args, **kwargs)
  File "C:\Users\lolof\PycharmProjects\nextdigital\venv\lib\site-packages\jinja2\environment.py", line 1008, in render
    return self.environment.handle_exception(exc_info, True)
  File "C:\Users\lolof\PycharmProjects\nextdigital\venv\lib\site-packages\jinja2\environment.py", line 780, in handle_exception
    reraise(exc_type, exc_value, tb)
  File "C:\Users\lolof\PycharmProjects\nextdigital\venv\lib\site-packages\jinja2\_compat.py", line 37, in reraise
    raise value.with_traceback(tb)
  File "C:\Users\lolof\PycharmProjects\nextdigital\app\templates\index.html", line 2, in top-level template code
    {% import 'bootstrap/wtf.html' as wtf %}
  File "C:\Users\lolof\PycharmProjects\nextdigital\app\templates\base.html", line 1, in top-level template code
    {% extends 'bootstrap/base.html' %}
  File "C:\Users\lolof\PycharmProjects\nextdigital\venv\lib\site-packages\flask_bootstrap\templates\bootstrap\base.html", line 1, in top-level template code
    {% block doc -%}
  File "C:\Users\lolof\PycharmProjects\nextdigital\venv\lib\site-packages\flask_bootstrap\templates\bootstrap\base.html", line 4, in block "doc"
    {%- block html %}
  File "C:\Users\lolof\PycharmProjects\nextdigital\venv\lib\site-packages\flask_bootstrap\templates\bootstrap\base.html", line 20, in block "html"
    {% block body -%}
  File "C:\Users\lolof\PycharmProjects\nextdigital\venv\lib\site-packages\flask_bootstrap\templates\bootstrap\base.html", line 23, in block "body"
    {% block content -%}
  File "C:\Users\lolof\PycharmProjects\nextdigital\app\templates\base.html", line 56, in block "content"
    {% block current_app_content %}{% endblock %}
  File "C:\Users\lolof\PycharmProjects\nextdigital\app\templates\index.html", line 9, in block "current_app_content"
    <img src="{{ url_for('static', nextdigital_logo1.png) }}"  alt="nextdigital 1logo">
  File "C:\Users\lolof\PycharmProjects\nextdigital\venv\lib\site-packages\jinja2\environment.py", line 430, in getattr
    return getattr(obj, attribute)
jinja2.exceptions.UndefinedError: 'nextdigital_logo1' is undefined
